Workbook

Sheet FSM Forecast
C2: ="Financial Statement Model for "&D5 -> Financial Statement Model for Micron
C3: $ in thousands except per share
C5: Company name | D5: Micron
C6: Ticker | D6: MU
C7: Circ break 1=off, 0=on | D7: 1
C8: Latest closing share price date | D8: 45937
C9: Latest closing share price | D9: 185.69
C10: Latest fiscal year end date | D10: 45897
C11: Shares outstanding (millions) | D11: 1122.466
C12: Active Case | D12: Base Case
B14: x | C14: INCOME STATEMENT
C15: Fiscal year | D15: =E15-1 -> 2023 | E15: =F15-1 -> 2024 | F15: 2025 | G15: 2026 | H15: =G15+1 -> 2027 | I15: =H15+1 -> 2028 | J15: =I15+1 -> 2029 | K15: =J15+1 -> 2030
C16: Fiscal year end date | D16: =DATE(2024,8,29)-364 -> 45169 | E16: =DATE(2025,8,28)-364 -> 45533 | F16: =D10 -> 45897 | G16: =DATE(2025,8,28)+364 -> 46261 | H16: =DATE(2026,8,27)+364 -> 46625 | I16: =DATE(2027,8,26)+371 -> 46996 | J16: =DATE(2028,8,31)+364 -> 47360 | K16: =DATE(2029,8,30)+364 -> 47724 | M16: Comment
C18: Revenue | D18: 15540 | E18: 25111 | F18: 37378 | G18: =F18*(1+G39) -> 54518.178 | H18: =G18*(1+H39) -> 67519.534 | I18: =H18*(1+I39) -> 74513.923 | J18: =I18*(1+J39) -> 78893.684 | K18: =J18*(1+K39) -> 83389.786 | M18: Prior year * (1+g)
C19: Cost of sales (enter as -) | D19: -16956 | E19: -19498 | F19: -22505 | G19: =G20-G18 -> -26375.894 | H19: =H20-H18 -> -36717.123 | I19: =I20-I18 -> -44991.506 | J19: =J20-J18 -> -52369.628 | K19: =K20-K18 -> -60357.527 | M19: Plug = Revenue - Gross Profit
C20: Gross Profit | D20: =SUM(D18:D19) -> -1416 | E20: =SUM(E18:E19) -> 5613 | F20: =SUM(F18:F19) -> 14873 | G20: =G18*G40 -> 28142.283 | H20: =H18*H40 -> 30802.411 | I20: =I18*I40 -> 29522.416 | J20: =J18*J40 -> 26524.057 | K20: =K18*K40 -> 23032.259 | M20: Revenue x Gross Profit Margin forecast
C21: Research & development (enter as -) | D21: -3114 | E21: -3430 | F21: -3798 | G21: =F21*(1+G41) -> -4132.224 | H21: =G21*(1+H41) -> -4514.0415 | I21: =H21*(1+I41) -> -4929.3333 | J21: =I21*(1+J41) -> -5382.832 | K21: =J21*(1+K41) -> -5878.0525 | M21: Revenue x R&D % of sales forecast
C22: Selling, general & administrative (enter as -) | D22: -920 | E22: -1129 | F22: -1205 | G22: =F22*(1+G42) -> -1235.125 | H22: =G22*(1+H42) -> -1266.0031 | I22: =H22*(1+I42) -> -1297.6532 | J22: =I22*(1+J42) -> -1330.0945 | K22: =J22*(1+K42) -> -1363.3469 | M22: Revenue x SG&A % of sales forecast
C23: Restructuring & asset impairments | D23: -171 | E23: -1 | F23: -39 | G23: 0 | H23: 0 | I23: 0 | J23: 0 | K23: 0
C24: Other operating income (expense), net | D24: -124 | E24: 251 | F24: -61 | G24: 0 | H24: 0 | I24: 0 | J24: 0 | K24: 0
C25: Operating profit (EBIT) | D25: =SUM(D20:D24) -> -5745 | E25: =SUM(E20:E24) -> 1304 | F25: =SUM(F20:F24) -> 9770 | G25: =SUM(G20:G22) -> 22774.934 | H25: =SUM(H20:H22) -> 25022.367 | I25: =SUM(I20:I22) -> 23295.43 | J25: =SUM(J20:J22) -> 19811.13 | K25: =SUM(K20:K22) -> 15790.859 | M25: Gross Profit - R&D - SG&A
C26: Interest income | D26: 468 | E26: 529 | F26: 496 | G26: =G169 -> 663.77892 | H26: =H169 -> 850.11784 | I26: =I169 -> 1434.4651 | J26: =J169 -> 2070.8525 | K26: =K169 -> 2661.7211 | M26: Reference from interest on cash schedule
C27: Interest expense (enter as -) | D27: -388 | E27: -562 | F27: -477 | G27: =-G152 -> -430.1425 | H27: =-H152 -> -417.3925 | I27: =-I152 -> -417.3925 | J27: =-J152 -> -417.3925 | K27: =-K152 -> -417.3925 | M27: Reference from interest expense schedule
C28: Other expense, net (enter as -) | D28: 7 | E28: -31 | F28: -135 | G28: =F28 -> -135 | H28: =G28 -> -135 | I28: =H28 -> -135 | J28: =I28 -> -135 | K28: =J28 -> -135 | M28: Straight-line
C29: Pretax profit | D29: =SUM(D25:D28) -> -5658 | E29: =SUM(E25:E28) -> 1240 | F29: =SUM(F25:F28) -> 9654 | G29: =SUM(G25:G28) -> 22873.571 | H29: =SUM(H25:H28) -> 25320.092 | I29: =SUM(I25:I28) -> 24177.502 | J29: =SUM(J25:J28) -> 21329.59 | K29: =SUM(K25:K28) -> 17900.188 | M29: EBIT + interest income less interest expense less other expense
C30: Taxes (enter expense as -) | D30: -177 | E30: -451 | F30: -1124 | G30: =-G29*G43 -> -3774.1392 | H30: =-H29*H43 -> -4177.8152 | I30: =-I29*I43 -> -3989.2879 | J30: =-J29*J43 -> -3519.3824 | K30: =-K29*K43 -> -2953.531 | M30: Pre-tax Profit x Tax Rate forecast
C31: Net income | D31: =SUM(D29:D30) -> -5835 | E31: =SUM(E29:E30) -> 789 | F31: =SUM(F29:F30) -> 8530 | G31: =SUM(G29:G30) -> 19099.432 | H31: =SUM(H29:H30) -> 21142.277 | I31: =SUM(I29:I30) -> 20188.214 | J31: =SUM(J29:J30) -> 17810.208 | K31: =SUM(K29:K30) -> 14946.657 | M31: Pre-tax Profit less taxes
C33: Depreciation & amortization | D33: 7756 | E33: 7780 | F33: 8352 | G33: =G116 -> 16187.277 | H33: =H116 -> 15738.472 | I33: =I116 -> 16343.677 | J33: =J116 -> 17372.288 | K33: =K116 -> 18170.91 | M33: Reference from D&A schedule
C34: EBITDA | D34: =D33+D25 -> 2011 | E34: =E33+E25 -> 9084 | F34: =F33+F25 -> 18122 | G34: =G33+G25 -> 38962.212 | H34: =H33+H25 -> 40760.839 | I34: =I33+I25 -> 39639.107 | J34: =J33+J25 -> 37183.418 | K34: =K33+K25 -> 33961.769
C35: Stock based compensation | D35: 596 | E35: 833 | F35: 972 | G35: =F35*(1+G39) -> 1417.7235 | H35: =G35*(1+H39) -> 1755.8186 | I35: =H35*(1+I39) -> 1937.7049 | J35: =I35*(1+J39) -> 2051.5988 | K35: =J35*(1+K39) -> 2168.5182 | M35: Assumption grow in line with revenue
C36: Adjusted EBITDA | D36: =SUM(D34:D35) -> 2607 | E36: =SUM(E34:E35) -> 9917 | F36: =SUM(F34:F35) -> 19094 | G36: =SUM(G34:G35) -> 40379.935 | H36: =SUM(H34:H35) -> 42516.657 | I36: =SUM(I34:I35) -> 41576.812 | J36: =SUM(J34:J35) -> 39235.017 | K36: =SUM(K34:K35) -> 36130.287 | M36: EBITDA + Stock-based compensation
C38: Growth rates & margins
C39: Revenue growth | E39: =E18/D18-1 -> 0.61589447 | F39: =F18/E18-1 -> 0.48851101 | G39: =G219 -> 0.45856327 | H39: =H219 -> 0.23847745 | I39: =I219 -> 0.10359059 | J39: =J219 -> 0.058777765 | K39: =K219 -> 0.056989372 | M39: Imported from scenario analysis
C40: Gross profit margin | D40: =D20/D18 -> -0.091119691 | E40: =E20/E18 -> 0.22352754 | F40: =F20/F18 -> 0.39790786 | G40: =G220 -> 0.5162 | H40: =H220 -> 0.4562 | I40: =I220 -> 0.3962 | J40: =J220 -> 0.3362 | K40: =K220 -> 0.2762 | M40: Imported from scenario analysis
C41: R&D % of sales | D41: =-(D21/D18) -> 0.2003861 | E41: =-(E21/E18) -> 0.13659352 | F41: =-(F21/F18) -> 0.10161057 | G41: =G221 -> 0.088 | H41: =H221 -> 0.0924 | I41: =I221 -> 0.092 | J41: =J221 -> 0.092 | K41: =K221 -> 0.092 | M41: Imported from scenario analysis
C42: SG&A % of sales | D42: =-(D22/D18) -> 0.059202059 | E42: =-(E22/E18) -> 0.044960376 | F42: =-(F22/F18) -> 0.032238215 | G42: =G222 -> 0.025 | H42: =H222 -> 0.025 | I42: =I222 -> 0.025 | J42: =J222 -> 0.025 | K42: =K222 -> 0.025 | M42: Imported from scenario analysis
C43: Tax rate | D43: =D30/D29 -> 0.031283139 | E43: =-E30/E29 -> 0.36370968 | F43: =-F30/F29 -> 0.11642842 | G43: 0.165 | H43: 0.165 | I43: 0.165 | J43: 0.165 | K43: 0.165 | M43: TS Assumption
B45: x | C45: BALANCE SHEET
C46: Fiscal year | E46: =F46-1 -> 2024 | F46: 2025 | G46: 2026 | H46: =G46+1 -> 2027 | I46: =H46+1 -> 2028 | J46: =I46+1 -> 2029 | K46: =J46+1 -> 2030
C47: Fiscal year end date | E47: =DATE(2025,8,28)-364 -> 45533 | F47: =D10 -> 45897 | G47: =DATE(2025,8,28)+364 -> 46261 | H47: =DATE(2026,8,27)+364 -> 46625 | I47: =DATE(2027,8,26)+371 -> 46996 | J47: =DATE(2028,8,31)+364 -> 47360 | K47: =DATE(2029,8,30)+364 -> 47724
...

Sheet Revenue Build
C2: Price / volume build
C3: Fiscal year | E3: 2024 | F3: 2025 | G3: 2026 | H3: =G3+1 -> 2027 | I3: =H3+1 -> 2028 | J3: =I3+1 -> 2029 | K3: =J3+1 -> 2030
C4: Fiscal year end date | E4: =DATE(2025,8,28)-364 -> 45533 | F4: ='FSM Forecast'!D10 -> 45897 | G4: =DATE(2025,8,28)+364 -> 46261 | H4: =DATE(2026,8,27)+364 -> 46625 | I4: =DATE(2027,8,26)+371 -> 46996 | J4: =DATE(2028,8,31)+364 -> 47360 | K4: =DATE(2029,8,30)+364 -> 47724
C5: Revenue by product
C6: Core products
C8: DRAM | E8: 17600 | F8: 28580 | G8: =F8*(1+G22) -> 43135.794 | H8: =G8*(1+H22) -> 54001.701 | I8: =H8*(1+I22) -> 59715.08 | J8: =I8*(1+J22) -> 63309.928 | K8: =J8*(1+K22) -> 67121.186
C9: NAND | E9: 7230 | F9: 8500 | G9: =F9*(1+G23) -> 10949.7 | H9: =G9*(1+H23) -> 12981.964 | I9: =H9*(1+I23) -> 14207.462 | J9: =I9*(1+J23) -> 14957.616 | K9: =J9*(1+K23) -> 15606.776
C10: Total Revenue | E10: =SUM(E8:E9) -> 24830 | F10: =SUM(F8:F9) -> 37080 | G10: =SUM(G8:G9) -> 54085.494 | H10: =SUM(H8:H9) -> 66983.665 | I10: =SUM(I8:I9) -> 73922.542 | J10: =SUM(J8:J9) -> 78267.544 | K10: =SUM(K8:K9) -> 82727.962
C11: % growth | F11: =F10/E10-1 -> 0.49335481 | G11: =G10/F10-1 -> 0.45861634 | H11: =H10/G10-1 -> 0.23847745 | I11: =I10/H10-1 -> 0.10359059 | J11: =J10/I10-1 -> 0.058777765 | K11: =K10/J10-1 -> 0.056989372
C13: Bit Demand Growth
C14: DRAM | G14: 0.17 | H14: 0.17 | I14: 0.14 | J14: 0.14 | K14: 0.14
C15: NAND | G15: 0.14 | H15: 0.14 | I15: 0.14 | J15: 0.12 | K15: 0.11
C17: Average Selling Price Change
C18: DRAM | G18: 0.29 | H18: 0.07 | I18: -0.03 | J18: -0.07 | K18: -0.07
C19: NAND | G19: 0.13 | H19: 0.04 | I19: -0.04 | J19: -0.06 | K19: -0.06
C21: Revenue Growth
C22: DRAM | G22: =(1+G14)*(1+G18)-1 -> 0.5093 | H22: =(1+H14)*(1+H18)-1 -> 0.2519 | I22: =(1+I14)*(1+I18)-1 -> 0.1058 | J22: =(1+J14)*(1+J18)-1 -> 0.0602 | K22: =(1+K14)*(1+K18)-1 -> 0.0602
C23: NAND | G23: =(1+G15)*(1+G19)-1 -> 0.2882 | H23: =(1+H15)*(1+H19)-1 -> 0.1856 | I23: =(1+I15)*(1+I19)-1 -> 0.0944 | J23: =(1+J15)*(1+J19)-1 -> 0.0528 | K23: =(1+K15)*(1+K19)-1 -> 0.0434

Sheet Sheet3
